<?xml version="1.0" ?>
<!-- =================================================================================== -->
<!-- |    This document was autogenerated by xacro from robot.urdf.xacro               | -->
<!-- |    EDITING THIS FILE BY HAND IS NOT RECOMMENDED                                 | -->
<!-- =================================================================================== -->
<robot name="lwa4p" xmlns:xacro="http://www.ros.org/wiki/xacro">
  <!-- common stuff -->
  <!-- see https://secure.wikimedia.org/wikipedia/en/wiki/List_of_moment_of_inertia_tensors -->
  <material name="Schunk/LightGrey">
    <color rgba="0.7 0.7 0.7 1.0"/>
  </material>
  <material name="Schunk/DarkGrey">
    <color rgba="0.4 0.4 0.4 1.0"/>
  </material>
  <material name="Schunk/Black">
    <color rgba="0.0 0.0 0.0 1.0"/>
  </material>
  <material name="Schunk/DarkGolden">
    <color rgba="0.4 0.4 0.3 1.0"/>
  </material>
  <material name="Schunk/Blue">
    <color rgba="0.0 0.0 0.8 1.0"/>
  </material>
  <!--pg70 gripper -->
  <!-- schunk lwa4p -->
  <gazebo>
    <plugin filename="libhwi_switch_gazebo_ros_control.so" name="ros_control">
      <robotNamespace>gripper</robotNamespace>
      <filterJointsParam>joint_names</filterJointsParam>
    </plugin>
  </gazebo>
  <!-- Used for fixing robot to Gazebo -->
  <link name="world"/>
  <!-- arm -->
  <!-- joint between base_link and lwa4p_extended_connector_link -->
  <joint name="arm_0_joint" type="fixed">
    <origin rpy="0 0 0.1" xyz="0 0 0.8"/>
    <parent link="world"/>
    <child link="arm_0_link"/>
  </joint>
  <link name="arm_0_link">
    <inertial>
      <origin rpy="0 0 0" xyz="0 0 0"/>
      <mass value="0.29364"/>
      <inertia ixx="0.01" ixy="0" ixz="0" iyy="0.01" iyz="0" izz="0.01"/>
    </inertial>
    <visual>
      <origin rpy="0 0 0" xyz="0 0 0"/>
      <geometry>
        <mesh filename="package://mp400_description/meshes/lwa4p/arm_0_link.dae"/>
      </geometry>
      <material name="Schunk/DarkGrey"/>
    </visual>
    <collision>
      <origin rpy="0 0 0" xyz="0 0 0"/>
      <geometry>
        <mesh filename="package://mp400_description/meshes/lwa4p/arm_0_link.stl"/>
      </geometry>
    </collision>
  </link>
  <joint name="arm_1_joint" type="revolute">
    <origin rpy="0 0 0" xyz="0 0 0.11"/>
    <parent link="arm_0_link"/>
    <child link="arm_1_link"/>
    <axis xyz="0 0 1"/>
    <calibration rising="2.1"/>
    <limit effort="300" lower="-2.95" upper="2.95" velocity="1.25"/>
  </joint>
  <!-- eff = "370" -->
  <link name="arm_1_link">
    <inertial>
      <mass value="0.29364"/>
      <inertia ixx="0.01" ixy="0" ixz="0" iyy="0.01" iyz="0" izz="0.01"/>
      <origin rpy="0 0 0" xyz="0 0 0"/>
    </inertial>
    <!--
      <inertial>
        <origin xyz="0 0 0" rpy="0 0 0" />
        <mass value="0.29364"/>
        <inertia ixx="0.01" ixy="0" ixz="0" iyy="0.01" iyz="0" izz="0.01" />
      </inertial>
-->
    <visual>
      <origin rpy="0 0 0" xyz="0 0 0"/>
      <geometry>
        <mesh filename="package://mp400_description/meshes/lwa4p/arm_1_link.dae"/>
      </geometry>
      <material name="Schunk/DarkGrey"/>
    </visual>
    <collision>
      <origin rpy="0 0 0" xyz="0 0 0"/>
      <geometry>
        <mesh filename="package://mp400_description/meshes/lwa4p/arm_1_link.stl"/>
      </geometry>
    </collision>
  </link>
  <!-- joint between arm_1_link and arm_2_link -->
  <joint name="arm_2_joint" type="revolute">
    <origin rpy="1.5708 0 0" xyz="0 0 0"/>
    <parent link="arm_1_link"/>
    <child link="arm_2_link"/>
    <axis xyz="0 0 1"/>
    <limit effort="250" lower="-2.95" upper="2.95" velocity="1.25"/>
    <!-- This is useful when the arm is mounted standing on a table -->
    <!-- <safety_controller k_position="20" k_velocity="25" soft_lower_limit="${-1.9 + safety_offset}" soft_upper_limit="${1.9 - safety_offset}" /> -->
  </joint>
  <!-- eff = "370" -->
  <link name="arm_2_link">
    <inertial>
      <mass value="0.29364"/>
      <inertia ixx="0.01" ixy="0" ixz="0" iyy="0.01" iyz="0" izz="0.01"/>
      <origin rpy="0 0 0" xyz="0 0 0"/>
    </inertial>
    <!--<inertial>
        <origin xyz="0 0 0" rpy="0 0 0"/>
        <mass value="1.68311"/>
        <inertia ixx="0.03" ixy="0" ixz="0" iyy="0.03" iyz="0" izz="0.03" />
      </inertial>-->
    <visual>
      <origin rpy="0 0 0" xyz="0 0 0"/>
      <geometry>
        <mesh filename="package://mp400_description/meshes/lwa4p/arm_2_link.dae"/>
      </geometry>
      <material name="Schunk/Blue"/>
    </visual>
    <collision>
      <origin rpy="0 0 0" xyz="0 0 0"/>
      <geometry>
        <mesh filename="package://mp400_description/meshes/lwa4p/arm_2_link.stl"/>
      </geometry>
    </collision>
  </link>
  <!-- joint between arm_2_link and arm_3_link -->
  <joint name="arm_3_joint" type="revolute">
    <origin rpy="0 3.14159 0" xyz="0 0.350 0"/>
    <parent link="arm_2_link"/>
    <child link="arm_3_link"/>
    <axis xyz="0 0 1"/>
    <limit effort="200" lower="-2.95" upper="2.95" velocity="1.25"/>
    <!--<safety_controller k_position="20" k_velocity="25" soft_lower_limit="${-2.7+ safety_offset}" soft_upper_limit="${2.7 - safety_offset}" />-->
  </joint>
  <!-- eff = "176" -->
  <link name="arm_3_link">
    <!-- <xacro:default_inertial mass="0.29364"/> 2.1-->
    <inertial>
      <origin rpy="0 0 1.5708" xyz="0 0 0"/>
      <mass value="0.29364"/>
      <inertia ixx="0.03" ixy="0" ixz="0" iyy="0.03" iyz="0" izz="0.03"/>
    </inertial>
    <visual>
      <origin rpy="0 0 0" xyz="0 0 0"/>
      <geometry>
        <mesh filename="package://mp400_description/meshes/lwa4p/arm_3_link.dae"/>
      </geometry>
      <material name="Schunk/DarkGrey"/>
    </visual>
    <collision>
      <origin rpy="0 0 0" xyz="0 0 0"/>
      <geometry>
        <mesh filename="package://mp400_description/meshes/lwa4p/arm_3_link.stl"/>
      </geometry>
    </collision>
  </link>
  <!-- joint between arm_3_link and arm_4_link -->
  <joint name="arm_4_joint" type="revolute">
    <origin rpy="-1.5708 3.14159 0" xyz="0 0 0"/>
    <parent link="arm_3_link"/>
    <child link="arm_4_link"/>
    <axis xyz="0 0 1"/>
    <limit effort="150" lower="-2.95" upper="2.95" velocity="1.25"/>
  </joint>
  <!-- eff = "176" -->
  <link name="arm_4_link">
    <inertial>
      <mass value="0.19364"/>
      <inertia ixx="0.01" ixy="0" ixz="0" iyy="0.01" iyz="0" izz="0.01"/>
      <origin rpy="0 0 0" xyz="0 0 0"/>
    </inertial>
    <!-- 0.29364 -->
    <!--<inertial>
        <origin xyz="0 0 0" rpy="0 0 0"/>
        <mass value="1.68311"/>
        <inertia ixx="0.03" ixy="0" ixz="0" iyy="0.03" iyz="0" izz="0.03" />
      </inertial>-->
    <visual>
      <origin rpy="0 0 0" xyz="0 0 0"/>
      <geometry>
        <mesh filename="package://mp400_description/meshes/lwa4p/arm_4_link.dae"/>
      </geometry>
      <material name="Schunk/Blue"/>
    </visual>
    <collision>
      <origin rpy="0 0 0" xyz="0 0 0"/>
      <geometry>
        <mesh filename="package://mp400_description/meshes/lwa4p/arm_4_link.stl"/>
      </geometry>
    </collision>
  </link>
  <!-- joint between arm_4_link and arm_5_link -->
  <joint name="arm_5_joint" type="revolute">
    <origin rpy="1.5708 0 3.14159" xyz="0 0.005263 0.305"/>
    <parent link="arm_4_link"/>
    <child link="arm_5_link"/>
    <axis xyz="0 0 1"/>
    <limit effort="100" lower="-2.95" upper="2.95" velocity="1.25"/>
  </joint>
  <!-- eff = "41.6" -->
  <link name="arm_5_link">
    <inertial>
      <mass value="0.15364"/>
      <inertia ixx="0.01" ixy="0" ixz="0" iyy="0.01" iyz="0" izz="0.01"/>
      <origin rpy="0 0 0" xyz="0 0 0"/>
    </inertial>
    <!-- 0.29364 -->
    <!--<inertial>
        <origin xyz="0 0 0" rpy="0 0 0"/>
        <mass value="0.807"/>
        <inertia ixx="0.03" ixy="0" ixz="0" iyy="0.03" iyz="0" izz="0.03" />
      </inertial>-->
    <visual>
      <origin rpy="0 0 0" xyz="0 0 0"/>
      <geometry>
        <mesh filename="package://mp400_description/meshes/lwa4p/arm_5_link.dae"/>
      </geometry>
      <material name="Schunk/DarkGrey"/>
    </visual>
    <collision>
      <origin rpy="0 0 0" xyz="0 0 0"/>
      <geometry>
        <mesh filename="package://mp400_description/meshes/lwa4p/arm_5_link.stl"/>
      </geometry>
    </collision>
  </link>
  <!-- joint between arm_5_link and arm_6_link -->
  <joint name="arm_6_joint" type="revolute">
    <origin rpy="-1.5708 0 0" xyz="0 0 0"/>
    <parent link="arm_5_link"/>
    <child link="arm_6_link"/>
    <axis xyz="0 0 1"/>
    <limit effort="50" lower="-2.947" upper="2.947" velocity="1.25"/>
    <!--safety_controller k_position="20" k_velocity="25" soft_lower_limit="${-2.09 + 0.01}" soft_upper_limit="${2.09 - 0.01}" /-->
  </joint>
  <link name="arm_6_link">
    <inertial>
      <mass value="0.10364"/>
      <inertia ixx="0.01" ixy="0" ixz="0" iyy="0.01" iyz="0" izz="0.01"/>
      <origin rpy="0 0 0" xyz="0 0 0"/>
    </inertial>
    <!-- 0.29364 -->
    <!--<inertial>
        <origin xyz="0 0 0" rpy="0 0 0"/>
        <mass value="0.819"/>
        <inertia ixx="0.01" ixy="0" ixz="0" iyy="0.01" iyz="0" izz="0.01" />
      </inertial>-->
    <visual>
      <origin rpy="0 0 0" xyz="0 0 0"/>
      <geometry>
        <mesh filename="package://mp400_description/meshes/lwa4p/arm_6_link.dae"/>
      </geometry>
      <material name="Schunk/DarkGrey"/>
    </visual>
    <collision>
      <origin rpy="0 0 0" xyz="0 0 0"/>
      <geometry>
        <mesh filename="package://mp400_description/meshes/lwa4p/arm_6_link.stl"/>
      </geometry>
    </collision>
  </link>
  <!-- joint between arm_6_link and tcp_link -->
  <!--<joint name="${name}_tcp_joint" type="fixed">
      <origin xyz="0 0 0.08" rpy="0 0 0" />
      <parent link="${name}_6_link"/>
      <child link="${name}_tcp_link"/>
    </joint>
    <link name="${name}_tcp_link">
    </link>-->
  <gazebo reference="arm_0_link">
    <gravity>true</gravity>
    <self_collide>false</self_collide>
    <material value="Schunk/DarkGrey"/>
  </gazebo>
  <gazebo reference="arm_1_link">
    <gravity>true</gravity>
    <self_collide>false</self_collide>
    <material value="Schunk/DarkGrey"/>
  </gazebo>
  <gazebo reference="arm_2_link">
    <gravity>true</gravity>
    <self_collide>false</self_collide>
    <material value="Schunk/Blue"/>
  </gazebo>
  <gazebo reference="arm_3_link">
    <gravity>true</gravity>
    <self_collide>false</self_collide>
    <material value="Schunk/DarkGrey"/>
  </gazebo>
  <gazebo reference="arm_4_link">
    <gravity>true</gravity>
    <self_collide>false</self_collide>
    <material value="Schunk/Blue"/>
  </gazebo>
  <gazebo reference="arm_5_link">
    <gravity>true</gravity>
    <self_collide>false</self_collide>
    <material value="Schunk/DarkGrey"/>
  </gazebo>
  <gazebo reference="arm_6_link">
    <gravity>true</gravity>
    <self_collide>false</self_collide>
    <material value="Schunk/DarkGrey"/>
  </gazebo>
  <transmission name="arm_1_trans">
    <type>transmission_interface/SimpleTransmission</type>
    <joint name="arm_1_joint">
      <hardwareInterface>hardware_interface/EffortJointInterface</hardwareInterface>
      <!--<hardwareInterface>PositionJointInterface</hardwareInterface>
        <hardwareInterface>VelocityJointInterface</hardwareInterface>-->
    </joint>
    <actuator name="arm_1_motor">
      <hardwareInterface>hardware_interface/EffortJointInterface</hardwareInterface>
      <mechanicalReduction>1</mechanicalReduction>
    </actuator>
  </transmission>
  <transmission name="arm_2_trans">
    <type>transmission_interface/SimpleTransmission</type>
    <joint name="arm_2_joint">
      <hardwareInterface>hardware_interface/EffortJointInterface</hardwareInterface>
      <!--<hardwareInterface>PositionJointInterface</hardwareInterface>
        <hardwareInterface>VelocityJointInterface</hardwareInterface>-->
    </joint>
    <actuator name="arm_2_motor">
      <hardwareInterface>hardware_interface/EffortJointInterface</hardwareInterface>
      <mechanicalReduction>1</mechanicalReduction>
    </actuator>
  </transmission>
  <transmission name="arm_3_trans">
    <type>transmission_interface/SimpleTransmission</type>
    <joint name="arm_3_joint">
      <hardwareInterface>hardware_interface/EffortJointInterface</hardwareInterface>
      <!--<hardwareInterface>PositionJointInterface</hardwareInterface>
        <hardwareInterface>VelocityJointInterface</hardwareInterface>-->
    </joint>
    <actuator name="arm_3_motor">
      <hardwareInterface>hardware_interface/EffortJointInterface</hardwareInterface>
      <mechanicalReduction>1</mechanicalReduction>
    </actuator>
  </transmission>
  <transmission name="arm_4_trans">
    <type>transmission_interface/SimpleTransmission</type>
    <joint name="arm_4_joint">
      <hardwareInterface>hardware_interface/EffortJointInterface</hardwareInterface>
      <!--<hardwareInterface>PositionJointInterface</hardwareInterface>
        <hardwareInterface>VelocityJointInterface</hardwareInterface>-->
    </joint>
    <actuator name="arm_4_motor">
      <hardwareInterface>hardware_interface/EffortJointInterface</hardwareInterface>
      <mechanicalReduction>1</mechanicalReduction>
    </actuator>
  </transmission>
  <transmission name="arm_5_trans">
    <type>transmission_interface/SimpleTransmission</type>
    <joint name="arm_5_joint">
      <hardwareInterface>hardware_interface/EffortJointInterface</hardwareInterface>
      <!--<hardwareInterface>PositionJointInterface</hardwareInterface>
        <hardwareInterface>VelocityJointInterface</hardwareInterface>-->
    </joint>
    <actuator name="arm_5_motor">
      <hardwareInterface>hardware_interface/EffortJointInterface</hardwareInterface>
      <mechanicalReduction>1</mechanicalReduction>
    </actuator>
  </transmission>
  <transmission name="arm_6_trans">
    <type>transmission_interface/SimpleTransmission</type>
    <joint name="arm_6_joint">
      <hardwareInterface>hardware_interface/EffortJointInterface</hardwareInterface>
      <!--<hardwareInterface>PositionJointInterface</hardwareInterface>
        <hardwareInterface>VelocityJointInterface</hardwareInterface>-->
    </joint>
    <actuator name="arm_6_motor">
      <hardwareInterface>hardware_interface/EffortJointInterface</hardwareInterface>
      <mechanicalReduction>1</mechanicalReduction>
    </actuator>
  </transmission>
  <material name="aluminum">
    <color rgba="0.5 0.5 0.5 1"/>
  </material>

  <joint name="pg70_palm_joint" type="fixed">
    <parent link="arm_6_link"/>
    <child link="pg70_palm_link"/>
    <origin rpy="0 0 0" xyz="0 0 0.075"/>
  </joint>
  <link name="pg70_palm_link">
    <visual>
      <geometry>
        <mesh filename="package://schunk_description/meshes/pg70/pg70.dae"/>
      </geometry>
      <material name="blue">
        <color rgba="0 0 1 1"/>
      </material>
    </visual>
    <collision>
      <geometry>
        <mesh filename="package://schunk_description/meshes/pg70/pg70.dae"/>
      </geometry>
      <material name="blue">
        <color rgba="0 0 1 1"/>
      </material>
    </collision>
  </link>
  <joint name="pg70_finger_left_joint" type="prismatic">
    <parent link="pg70_palm_link"/>
    <child link="pg70_finger_left_link"/>
    <limit effort="100" lower="-0.001" upper="0.04" velocity="2.0"/>
    <origin xyz="0 0 0.0789" rpy="0 0 0"/>
    <axis xyz="0 1 0"/>
  </joint>
  <link name="pg70_finger_left_link">
    <visual>
      <geometry>
        <box size="0.03 0.01 0.01"/>
      </geometry>
      <material name="black">
        <color rgba="0 0 0 1"/>
      </material>
    </visual>
    <collision>
      <geometry>
        <box size="0.03 0.01 0.01"/>
      </geometry>
      <material name="black"/>
    </collision>
  </link>
  <joint name="pg70_fingertip_left_joint" type="fixed" >
      <parent link="pg70_finger_left_link" />
      <child link="pg70_fingertip_left_link" />
      <origin xyz="0 0.01 0.045" rpy="0 0 0"/>
    </joint>

    <link name="pg70_fingertip_left_link">
      <visual>
        <geometry>
          <box size="0.03 0.01 0.1"/>
        </geometry>
        <material name="silver">
          <color rgba="0.8 0.8 0.8 1"/>
        </material>
      </visual>
      <collision>
        <geometry>
          <box size="0.03 0.01 0.1"/>
        </geometry>
	<material name="black"/>
      </collision>
    </link>

    <!-- camera body, with origin at bottom screw mount -->
    <joint name="camera_joint" type="fixed">
      <origin rpy="0 0 0" xyz="0.1 0 0.8"/>
      <parent link="world"/>
      <child link="camera_link"/>
    </joint>
    <link name="camera_link">
      <visual>
        <origin rpy="0.77079632679 0 1.57079632679" xyz="0.0149 0.0 0.0125"/>
        <!--<origin xyz="-0.25 0.0 1.425" rpy="${M_PI/2} 0 ${-M_PI/2}"/>-->
        <geometry>
          <!-- <box size="${d435_cam_width} ${d435_cam_height} ${d435_cam_depth}"/> -->
          <mesh filename="package://mp400_description/meshes/d435_camera/d435.dae"/>
          <!--<mesh filename="package://realsense2_camera/meshes/d435/d435.dae" />-->
        </geometry>
        <material name="aluminum"/>
      </visual>
      <collision>
        <origin rpy="0 0 0" xyz="0.0 0.0 0.0125"/>
        <!--<origin xyz="0.0 0.0 1.425" rpy="0 0 0"/>-->
        <geometry>
          <box size="0.02505 0.09 0.025"/>
        </geometry>
      </collision>
      <inertial>
        <!-- The following are not reliable values, and should not be used for modeling -->
        <mass value="0.564"/>
        <origin xyz="0 0 0"/>
        <inertia ixx="0.003881243" ixy="0.0" ixz="0.0" iyy="0.000498940" iyz="0.0" izz="0.003879257"/>
      </inertial>
    </link>
    <!-- camera depth joints and links -->
    <joint name="camera_depth_joint" type="fixed">
      <origin rpy="0 0 0" xyz="0.0149 0.0175 0.0125"/>
      <parent link="camera_link"/>
      <child link="camera_depth_frame"/>
    </joint>
    <link name="camera_depth_frame"/>
    <joint name="camera_depth_optical_joint" type="fixed">
      <origin rpy="-1.57079632679 0 -1.57079632679" xyz="0 0 0"/>
      --&gt;

      <!--<origin xyz="0 0 0" rpy="0 0 0" />-->
      <parent link="camera_depth_frame"/>
      <child link="camera_depth_optical_frame"/>
    </joint>
    <link name="camera_depth_optical_frame"/>
    <!-- camera left IR joints and links -->
    <joint name="camera_left_ir_joint" type="fixed">
      <origin rpy="0 0 0" xyz="0 0.0 0"/>
      <parent link="camera_depth_frame"/>
      <child link="camera_left_ir_frame"/>
    </joint>
    <link name="camera_left_ir_frame"/>
    <joint name="camera_left_ir_optical_joint" type="fixed">
      <origin rpy="-1.57079632679 0 -1.57079632679" xyz="0 0 0"/>
      <parent link="camera_left_ir_frame"/>
      <child link="camera_left_ir_optical_frame"/>
    </joint>
    <link name="camera_left_ir_optical_frame"/>
    <!-- camera right IR joints and links -->
    <joint name="camera_right_ir_joint" type="fixed">
      <origin rpy="0 0 0" xyz="0 -0.05 0"/>
      <parent link="camera_depth_frame"/>
      <child link="camera_right_ir_frame"/>
    </joint>
    <link name="camera_right_ir_frame"/>
    <joint name="camera_right_ir_optical_joint" type="fixed">
      <origin rpy="-1.57079632679 0 -1.57079632679" xyz="0 0 0"/>
      <parent link="camera_right_ir_frame"/>
      <child link="camera_right_ir_optical_frame"/>
    </joint>
    <link name="camera_right_ir_optical_frame"/>
    <!-- camera color joints and links -->
    <joint name="camera_color_joint" type="fixed">
      <origin rpy="0 0 0" xyz="0 0.015 0"/>
      <parent link="camera_depth_frame"/>
      <child link="camera_color_frame"/>
    </joint>
    <link name="camera_color_frame"/>
    <joint name="camera_color_optical_joint" type="fixed">
      <origin rpy="-1.57079632679 0 -1.57079632679" xyz="0 0 0"/>
      <parent link="camera_color_frame"/>
      <child link="camera_color_optical_frame"/>
    </joint>
    <link name="camera_color_optical_frame"/>

  <!-- extensions -->
  <gazebo reference="pg70_palm_link">
    <gravity>true</gravity>
    <self_collide>false</self_collide>
    <material>Schunk/LightGrey</material>
  </gazebo>
  <gazebo reference="pg70_finger_left_link">
    <gravity>true</gravity>
    <self_collide>false</self_collide>
    <material>Schunk/LightGrey</material>
  </gazebo>
  <gazebo reference="pg70_finger_right_link">
    <gravity>true</gravity>
    <self_collide>false</self_collide>
    <material>Schunk/LightGrey</material>
  </gazebo>
  <!-- finger1 -->
  <transmission name="pg70_finger_left_trans">
    <type>transmission_interface/SimpleTransmission</type>
    <joint name="pg70_finger_left_joint">
      <hardwareInterface>EffortJointInterface</hardwareInterface>
      <hardwareInterface>PositionJointInterface</hardwareInterface>
      <hardwareInterface>VelocityJointInterface</hardwareInterface>
    </joint>
    <actuator name="pg70_finger_left_motor">
      <mechanicalReduction>0.5</mechanicalReduction>
    </actuator>
  </transmission>
  <!-- finger2 - mimic -->
  <transmission name="pg70_finger_right_trans">
    <type>transmission_interface/SimpleTransmission</type>
    <joint name="pg70_finger_right_joint">
      <hardwareInterface>EffortJointInterface</hardwareInterface>
      <hardwareInterface>PositionJointInterface</hardwareInterface>
      <hardwareInterface>VelocityJointInterface</hardwareInterface>
    </joint>
    <actuator name="pg70_finger_right_motor">
      <mechanicalReduction>0.5</mechanicalReduction>
    </actuator>
  </transmission>
  <!-- gazebo_plugin for arm -->
  <gazebo>
    <plugin filename="libhwi_switch_gazebo_ros_control.so" name="ros_control">
      <robotNamespace>arm</robotNamespace>
      <filterJointsParam>joint_names</filterJointsParam>
    </plugin>
  </gazebo>
</robot>
