<?xml version="1.0" ?>
<!-- =================================================================================== -->
<!-- |    This document was autogenerated by xacro from mp_400.urdf.xacro              | -->
<!-- |    EDITING THIS FILE BY HAND IS NOT RECOMMENDED                                 | -->
<!-- =================================================================================== -->
<!-- Materials -->
<robot name="mp_400" xmlns:xacro="http://www.ros.org/wiki/xacro">
  <gazebo reference="base_link">
    <gravity>true</gravity>
    <self_collide>false</self_collide>
  </gazebo>
  <gazebo reference="castor_wheel_link">
    <gravity>true</gravity>
    <self_collide>false</self_collide>
  </gazebo>
  <gazebo reference="fixed_wheel_link">
    <gravity>true</gravity>
    <self_collide>false</self_collide>
  </gazebo>
  <gazebo reference="laserscanner_1_link">
    <sensor name="laserscanner_1_link" type="ray">
      <pose>0 0 0 0 0 0</pose>
      <visualize>false</visualize>
      <update_rate>40</update_rate>
      <ray>
        <scan>
          <horizontal>
            <samples>720</samples>
            <resolution>1</resolution>
            <min_angle>-0.785398</min_angle>
            <max_angle>0.785398</max_angle>
          </horizontal>
        </scan>
        <range>
          <min>0.10</min>
          <max>30.0</max>
          <resolution>0.05</resolution>
        </range>
        <noise>
          <type>gaussian</type>
          <!-- Noise parameters based on published spec for Hokuyo laser
                   achieving "+-30mm" accuracy at range < 10m.  A mean of 0.0m and
                   stddev of 0.01m will put 99.7% of samples within 0.03m of the true
                   reading. -->
          <mean>0.0</mean>
          <stddev>0.01</stddev>
        </noise>
      </ray>
      <plugin filename="libgazebo_ros_laser.so" name="laserscanner_1_link">
        <topicName>sick/scan</topicName>
        <frameName>laserscanner_1_link</frameName>
      </plugin>
    </sensor>
  </gazebo>
  <gazebo>
    <plugin filename="libgazebo_ros_planar_move.so" name="mp_400_controller">
      <commandTopic>cmd_vel</commandTopic>
      <odometryTopic>odom</odometryTopic>
      <odometryFrame>odom</odometryFrame>
      <odometryRate>20.0</odometryRate>
      <robotBaseFrame>base_link</robotBaseFrame>
    </plugin>
  </gazebo>
  <!--++++++++++++++++++++++++++++++base_link++++++++++++++++++++++++++++++++++++++++++++++++++++-->
  <!--++++++++++++++++++++body++++++++++++++++++++++++++++-->
  <link name="base_link">
    <inertial>
      <mass value="30"/>
      <origin rpy="0 0 0" xyz="0 0 0"/>
      <inertia ixx="1.71402" ixy="0.0" ixz="0.0" iyy="0.8856" iyz="0.0" izz="2.5725"/>
    </inertial>
    <visual name="body">
      <origin rpy="0 0 1.57" xyz="0.0 0.0 0."/>
      <geometry>
        <mesh filename="package://neo_mp_400/robot_model/mp_400/meshes/MP-400-BODY.dae" scale="0.001 0.001 0.001"/>
        <!--cylinder length="0.381" radius="0.2545"/-->
        <!--box size="0.445 0.277 0.17"/-->
      </geometry>
    </visual>
    <collision name="body_collision">
      <origin rpy="0 0 1.57" xyz="0.0 0.0 0.0"/>
      <geometry>
        <mesh filename="package://neo_mp_400/robot_model/mp_400/meshes/MP-400-BODY.dae" scale="0.001 0.001 0.001"/>
        <!--cylinder length="0.381" radius="0.2545"/-->
      </geometry>
    </collision>
  </link>
  <joint name="wheel_front_left_joint" type="fixed">
    <origin rpy="0 0 1.57" xyz="0.165 0.155 0.036"/>
    <axis xyz="0 1 0"/>
    <joint_properties damping="1" friction="1"/>
    <limit effort="1000.0" lower="-1e+16" upper="1e+16" velocity="3.5"/>
    <parent link="base_link"/>
    <child link="wheel_front_left_link"/>
  </joint>
  <link name="wheel_front_left_link" type="wheel">
    <inertial>
      <mass value="3.5"/>
      <origin rpy="0 0 0" xyz="0.000000010 -0.045437214 -0.073569633"/>
      <inertia ixx="13.177588678963057" ixy="-0.00000019386313414965295" ixz="-0.0000007636494859403484" iyy="8.48847991205267" iyz="-2.366298925984707" izz="7.157972023102095"/>
    </inertial>
    <visual name="caster_wheel">
      <origin rpy="0 0 0" xyz="0 0 0"/>
      <geometry>
        <mesh filename="package://neo_mp_400/robot_model/mp_400/meshes/MP-400-CASTER-WHEEL.dae" scale="0.001 0.001 0.001"/>
      </geometry>
    </visual>
    <collision>
      <origin rpy="0 0 0" xyz="0 0. 0"/>
      <geometry>
        <mesh filename="package://neo_mp_400/robot_model/mp_400/meshes/MP-400-CASTER-WHEEL.dae" scale="0.001 0.001 0.001"/>
      </geometry>
    </collision>
  </link>
  <joint name="wheel_back_left_joint" type="fixed">
    <origin rpy="0 0 1.57" xyz="-0.220 0.155 0.036"/>
    <axis xyz="0 1 0"/>
    <joint_properties damping="1" friction="1"/>
    <limit effort="1000.0" lower="-1e+16" upper="1e+16" velocity="3.5"/>
    <parent link="base_link"/>
    <child link="wheel_back_left_link"/>
  </joint>
  <link name="wheel_back_left_link" type="wheel">
    <inertial>
      <mass value="3.5"/>
      <origin rpy="0 0 0" xyz="0.000000010 -0.045437214 -0.073569633"/>
      <inertia ixx="13.177588678963057" ixy="-0.00000019386313414965295" ixz="-0.0000007636494859403484" iyy="8.48847991205267" iyz="-2.366298925984707" izz="7.157972023102095"/>
    </inertial>
    <visual name="caster_wheel">
      <origin rpy="0 0 0" xyz="0 0 0"/>
      <geometry>
        <mesh filename="package://neo_mp_400/robot_model/mp_400/meshes/MP-400-CASTER-WHEEL.dae" scale="0.001 0.001 0.001"/>
      </geometry>
    </visual>
    <collision>
      <origin rpy="0 0 0" xyz="0 0. 0"/>
      <geometry>
        <mesh filename="package://neo_mp_400/robot_model/mp_400/meshes/MP-400-CASTER-WHEEL.dae" scale="0.001 0.001 0.001"/>
      </geometry>
    </collision>
  </link>
  <joint name="wheel_front_right_joint" type="fixed">
    <origin rpy="0 0 1.57" xyz="0.165 -0.155 0.036"/>
    <axis xyz="0 1 0"/>
    <joint_properties damping="1" friction="1"/>
    <limit effort="1000.0" lower="-1e+16" upper="1e+16" velocity="3.5"/>
    <parent link="base_link"/>
    <child link="wheel_front_right_link"/>
  </joint>
  <link name="wheel_front_right_link" type="wheel">
    <inertial>
      <mass value="3.5"/>
      <origin rpy="0 0 0" xyz="0.000000010 -0.045437214 -0.073569633"/>
      <inertia ixx="13.177588678963057" ixy="-0.00000019386313414965295" ixz="-0.0000007636494859403484" iyy="8.48847991205267" iyz="-2.366298925984707" izz="7.157972023102095"/>
    </inertial>
    <visual name="caster_wheel">
      <origin rpy="0 0 0" xyz="0 0 0"/>
      <geometry>
        <mesh filename="package://neo_mp_400/robot_model/mp_400/meshes/MP-400-CASTER-WHEEL.dae" scale="0.001 0.001 0.001"/>
      </geometry>
    </visual>
    <collision>
      <origin rpy="0 0 0" xyz="0 0. 0"/>
      <geometry>
        <mesh filename="package://neo_mp_400/robot_model/mp_400/meshes/MP-400-CASTER-WHEEL.dae" scale="0.001 0.001 0.001"/>
      </geometry>
    </collision>
  </link>
  <joint name="wheel_back_right_joint" type="fixed">
    <origin rpy="0 0 1.57" xyz="-0.220 -0.155 0.036"/>
    <axis xyz="0 1 0"/>
    <joint_properties damping="1" friction="1"/>
    <limit effort="1000.0" lower="-1e+16" upper="1e+16" velocity="3.5"/>
    <parent link="base_link"/>
    <child link="wheel_back_right_link"/>
  </joint>
  <link name="wheel_back_right_link" type="wheel">
    <inertial>
      <mass value="3.5"/>
      <origin rpy="0 0 0" xyz="0.000000010 -0.045437214 -0.073569633"/>
      <inertia ixx="13.177588678963057" ixy="-0.00000019386313414965295" ixz="-0.0000007636494859403484" iyy="8.48847991205267" iyz="-2.366298925984707" izz="7.157972023102095"/>
    </inertial>
    <visual name="caster_wheel">
      <origin rpy="0 0 0" xyz="0 0 0"/>
      <geometry>
        <mesh filename="package://neo_mp_400/robot_model/mp_400/meshes/MP-400-CASTER-WHEEL.dae" scale="0.001 0.001 0.001"/>
      </geometry>
    </visual>
    <collision>
      <origin rpy="0 0 0" xyz="0 0. 0"/>
      <geometry>
        <mesh filename="package://neo_mp_400/robot_model/mp_400/meshes/MP-400-CASTER-WHEEL.dae" scale="0.001 0.001 0.001"/>
      </geometry>
    </collision>
  </link>
  <joint name="fixed_wheel_right_joint" type="fixed">
    <origin rpy="0 0 -1.57" xyz="0. -0.26 0.075"/>
    <axis xyz="0 1 0"/>
    <limit effort="1000.0" lower="-1e+16" upper="1e+16" velocity="3.5"/>
    <joint_properties damping="1" friction="1"/>
    <parent link="base_link"/>
    <child link="fixed_wheel_right_link"/>
  </joint>
  <link name="fixed_wheel_right_link" type="wheel">
    <inertial>
      <mass value="5.3"/>
      <origin rpy="0 0 0" xyz="0.000000143 -0.04248127 0.073712479"/>
      <inertia ixx="46.639251649513" ixy="0.0000023227242816" ixz="-0.000001619382358553578" iyy="25.926276619468705" iyz="-0.0000008220581770145895" izz="25.78086321479202"/>
    </inertial>
    <visual name="fixed_wheel">
      <origin rpy="0 0 0" xyz="0 0 0.0"/>
      <geometry>
        <mesh filename="package://neo_mp_400/robot_model/mp_400/meshes/MP-400-FIXED-WHEEL.dae" scale="0.001 0.001 0.001"/>
      </geometry>
    </visual>
    <collision>
      <origin rpy=" 0 0 0" xyz="0. 0 0"/>
      <geometry>
        <mesh filename="package://neo_mp_400/robot_model/mp_400/meshes/MP-400-FIXED-WHEEL.dae" scale="0.001 0.001 0.001"/>
      </geometry>
    </collision>
  </link>
  <joint name="fixed_wheel_left_joint" type="fixed">
    <origin rpy="0 0 1.57" xyz="-0. 0.26 0.075"/>
    <axis xyz="0 1 0"/>
    <limit effort="1000.0" lower="-1e+16" upper="1e+16" velocity="3.5"/>
    <joint_properties damping="1" friction="1"/>
    <parent link="base_link"/>
    <child link="fixed_wheel_left_link"/>
  </joint>
  <link name="fixed_wheel_left_link" type="wheel">
    <inertial>
      <mass value="5.3"/>
      <origin rpy="0 0 0" xyz="0.000000143 -0.04248127 0.073712479"/>
      <inertia ixx="46.639251649513" ixy="0.0000023227242816" ixz="-0.000001619382358553578" iyy="25.926276619468705" iyz="-0.0000008220581770145895" izz="25.78086321479202"/>
    </inertial>
    <visual name="fixed_wheel">
      <origin rpy="0 0 0" xyz="0 0 0.0"/>
      <geometry>
        <mesh filename="package://neo_mp_400/robot_model/mp_400/meshes/MP-400-FIXED-WHEEL.dae" scale="0.001 0.001 0.001"/>
      </geometry>
    </visual>
    <collision>
      <origin rpy=" 0 0 0" xyz="0. 0 0"/>
      <geometry>
        <mesh filename="package://neo_mp_400/robot_model/mp_400/meshes/MP-400-FIXED-WHEEL.dae" scale="0.001 0.001 0.001"/>
      </geometry>
    </collision>
  </link>
  <joint name="lidar_1_joint" type="fixed">
    <axis xyz="0 1 0"/>
    <origin rpy="0 3.14 3.14" xyz="0.230 0 0.110"/>
    <parent link="base_link"/>
    <child link="lidar_1_link"/>
  </joint>
  <link name="lidar_1_link" type="laser">
    <inertial>
      <mass value="0.001"/>
      <origin rpy="0 0 0" xyz="0 0 0"/>
      <inertia ixx="0.0001" ixy="0" ixz="0" iyy="0.000001" iyz="0" izz="0.0001"/>
    </inertial>
    <visual>
      <!-- SICK S3 sensor: Uncomment/Comment it out if required  -->
      <origin rpy="-1.57 0 3.14" xyz="0 0 -0.11"/>
      <geometry>
        <mesh filename="package://neo_mp_400/robot_model/mp_400/meshes/SICK-S300.dae" scale="0.001 0.001 0.001"/>
      </geometry>
    </visual>
    <collision>
      <origin rpy="-1.57 0 3.14" xyz="0 0 -0.11"/>
      <geometry>
        <mesh filename="package://neo_mp_400/robot_model/mp_400/meshes/SICK-S300.dae" scale="0.001 0.001 0.001"/>
      </geometry>
    </collision>
    <!-- Microscan 3 sensor: Uncomment/Comment it out if required  -->
    <!--<origin xyz="-0.0 0 -0.06" rpy="1.57 0 0" />
      <geometry>
      <mesh filename="package://neo_mp_400/robot_model/mp_400/meshes/SICK-MICROSCAN3.dae" scale="0.001 0.001 0.001" />
      </geometry>
      </visual>
      <collision>
 <origin xyz="-0.0 0 -0.06" rpy="1.57 0 0" />
      <geometry>
        <mesh filename="package://neo_mp_400/robot_model/mp_400/meshes/SICK-MICROSCAN3.dae" scale="0.001 0.001 0.001" />
        </geometry>
      </collision> -->
  </link>
  <joint name="imu_1_joint" type="fixed">
    <axis xyz="0 1 0"/>
    <origin rpy="0 0 3.14" xyz="0.100 0 0.300"/>
    <parent link="base_link"/>
    <child link="imu_1_link"/>
  </joint>
  <link name="imu_1_link">
    <inertial>
      <mass value="0.001"/>
      <origin rpy="0 0 0" xyz="0 0 0"/>
      <inertia ixx="0.0001" ixy="0" ixz="0" iyy="0.000001" iyz="0" izz="0.0001"/>
    </inertial>
  </link>
  <!--+++++++++++++++++++ Ultra Sonic ++++++++++++++++++++++++-->
  <!-- SENSOR 1 -->
  <!-- xacro:us_sensor name="us_1" parent="base_link">
    <origin xyz="0.100 0 0.300" rpy="0 3.14 3.14" />
  </xacro:us_sensor-->
  <!-- SENSOR 2 -->
  <!-- xacro:us_sensor name="us_2" parent="base_link">
    <origin xyz="0.110 0 0.300" rpy="0 3.14 3.14" />
  </xacro:us_sensor-->
  <!-- SENSOR 3 -->
  <!-- xacro:us_sensor name="us_3" parent="base_link">
    <origin xyz="0.120 0 0.300" rpy="0 3.14 3.14" />
  </xacro:us_sensor-->
  <!-- SENSOR 4 -->
  <!-- xacro:us_sensor name="us_4" parent="base_link">
    <origin xyz="0.130 0 0.300" rpy="0 3.14 3.14" />
  </xacro:us_sensor-->
  <!-- SENSOR 5 -->
  <!-- xacro:us_sensor name="us_5" parent="base_link">
    <origin xyz="0.140 0 0.300" rpy="0 3.14 3.14" />
  </xacro:us_sensor-->
  <!-- SENSOR 6 -->
  <!-- xacro:us_sensor name="us_6" parent="base_link">
    <origin xyz="0.150 0 0.300" rpy="0 3.14 3.14" />
  </xacro:us_sensor-->
  <!-- SENSOR 7 -->
  <!-- xacro:us_sensor name="us_7" parent="base_link">
    <origin xyz="0.160 0 0.300" rpy="0 3.14 3.14" />
  </xacro:us_sensor-->
  <!-- SENSOR 8 -->
  <!-- xacro:us_sensor name="us_8" parent="base_link">
    <origin xyz="0.170 0 0.300" rpy="0 3.14 3.14" />
  </xacro:us_sensor-->
  <!-- SENSOR 9 -->
  <!-- xacro:us_sensor name="us_9" parent="base_link">
    <origin xyz="0.180 0 0.300" rpy="0 3.14 3.14" />
  </xacro:us_sensor-->
  <!-- SENSOR 10 -->
  <!-- xacro:us_sensor name="us_10" parent="base_link">
    <origin xyz="0.100 0 0.300" rpy="0 3.14 3.14" />
  </xacro:us_sensor-->
  <!-- SENSOR 11 -->
  <!-- xacro:us_sensor name="us_11" parent="base_link">
    <origin xyz="0.100 0 0.300" rpy="0 3.14 3.14" />
  </xacro:us_sensor-->
  <!-- SENSOR 12 -->
  <!-- xacro:us_sensor name="us_12" parent="base_link">
    <origin xyz="0.190 0 0.300" rpy="0 3.14 3.14" />
  </xacro:us_sensor-->
  <!-- SENSOR 13 -->
  <!-- xacro:us_sensor name="us_13" parent="base_link">
    <origin xyz="0.200 0 0.300" rpy="0 3.14 3.14" />
  </xacro:us_sensor-->
  <!-- SENSOR 14 -->
  <!-- xacro:us_sensor name="us_14" parent="base_link">
    <origin xyz="0.210 0 0.300" rpy="0 3.14 3.14" />
  </xacro:us_sensor-->
  <!-- SENSOR 15 -->
  <!-- xacro:us_sensor name="us_15" parent="base_link">
    <origin xyz="0.220 0 0.300" rpy="0 3.14 3.14" />
  </xacro:us_sensor-->
  <!-- SENSOR 16 -->
  <!-- xacro:us_sensor name="us_16" parent="base_link">
    <origin xyz="0.230 0 0.300" rpy="0 3.14 3.14" />
  </xacro:us_sensor-->


  <!--+++++++++++++++++++laserscanner_back_joint++++++++++++++++++++++++-->
  <joint name="laserscanner_back_joint" type="fixed">
    <axis xyz="0 1 0"/>
    <origin rpy="3.14 0 3.14" xyz="-0.354 0 0.110"/>
    <parent link="base_link"/>
    <child link="laserscanner_back_link"/>
  </joint>
  <!--+++++++++++++++++++laserscanner_back_link++++++++++++++++++++++++-->
  <link name="laserscanner_back_link" type="laser">
    <inertial>
      <mass value="0.001"/>
      <origin rpy="0 0 0" xyz="0 0 0"/>
      <inertia ixx="0.0001" ixy="0" ixz="0" iyy="0.000001" iyz="0" izz="0.0001"/>
    </inertial>
    <visual>
      <origin rpy="0 0 -1.57" xyz="0 0 0"/>
      <geometry>
        <mesh filename="package://mp400_description/meshes/mp400/sick_s300.stl"/>
      </geometry>
      <material name="Neobotix/Yellow"/>
    </visual>
    <collision>
      <origin rpy="0 0 0" xyz="0 0 0"/>
      <geometry>
        <cylinder length="0.154" radius="0.053"/>
      </geometry>
    </collision>
  </link>

  <!--+++++++++++++++++++laserscanner_front_joint++++++++++++++++++++++++-->
  <joint name="laserscanner_front_joint" type="fixed">
    <axis xyz="0 1 0"/>
    <origin rpy="3.14 0 0" xyz="0.230 0 0.110"/>
    <parent link="base_link"/>
    <child link="laserscanner_front_link"/>
  </joint>
  <!--+++++++++++++++++++laserscanner_front_link++++++++++++++++++++++++-->
  <link name="laserscanner_front_link" type="laser">
    <inertial>
      <mass value="0.001"/>
      <origin rpy="0 0 0" xyz="0 0 0"/>
      <inertia ixx="0.0001" ixy="0" ixz="0" iyy="0.000001" iyz="0" izz="0.0001"/>
    </inertial>
    <visual>
      <origin rpy="0 0 -1.57" xyz="0 0 0"/>
      <geometry>
        <mesh filename="package://mp400_description/meshes/mp400/sick_s300.stl"/>
      </geometry>
      <material name="Neobotix/Yellow"/>
    </visual>
    <collision>
      <origin rpy="0 0 0" xyz="0 0 0"/>
      <geometry>
        <cylinder length="0.154" radius="0.053"/>
      </geometry>
    </collision>
  </link>

  <joint name="baselink_to_arm_mount" type="fixed">
    <parent link="base_link"/>
    <child link="arm_mount"/>
    <origin rpy="0 0 0" xyz="0.0 0.0 0.222"/>
  </joint>
  <!--+++++++++++++++++arm_mount_link+++++++++++++++++++-->
  <link name="arm_mount">
    <visual>
      <geometry>
        <box size="0.45 0.45 0.01"/>
      </geometry>
      <origin rpy="0 0 0" xyz="0.025 0 0.223"/>
      <material name="Schunk/LightGrey"/>
    </visual>
  </link>
  <link name="schunk_base_link">
    <origin rpy="0 0 0" xyz="0 0 3.14"/>
  </link>
  <joint name="arm_robot_joint" type="fixed">
    <parent link="arm_mount"/>
    <child link="schunk_base_link"/>
    <origin rpy="0 0 0" xyz="0.025 0 0.4"/>
  </joint>



  <joint name="arm_0_joint" type="fixed">
    <origin rpy="0 0 0.1" xyz="0 0 0"/>
    <parent link="schunk_base_link"/>
    <child link="arm_0_link"/>
  </joint>
  <link name="arm_0_link">
    <inertial>
      <origin rpy="0 0 0" xyz="0 0 0"/>
      <mass value="0.29364"/>
      <inertia ixx="0.01" ixy="0" ixz="0" iyy="0.01" iyz="0" izz="0.01"/>
    </inertial>
    <visual>
      <origin rpy="0 0 0" xyz="0 0 0"/>
      <geometry>
        <mesh filename="package://mp400_description/meshes/lwa4p/arm_0_link.dae"/>
      </geometry>
      <material name="Schunk/DarkGrey"/>
    </visual>
    <collision>
      <origin rpy="0 0 0" xyz="0 0 0"/>
      <geometry>
        <mesh filename="package://mp400_description/meshes/lwa4p/arm_0_link.stl"/>
      </geometry>
    </collision>
  </link>
  <joint name="arm_1_joint" type="revolute">
    <origin rpy="0 0 0" xyz="0 0 0.11"/>
    <parent link="arm_0_link"/>
    <child link="arm_1_link"/>
    <axis xyz="0 0 1"/>
    <calibration rising="2.1"/>
    <limit effort="300" lower="-2.95" upper="2.95" velocity="1.25"/>
  </joint>
  <!-- eff = "370" -->
  <link name="arm_1_link">
    <inertial>
      <mass value="0.29364"/>
      <inertia ixx="0.01" ixy="0" ixz="0" iyy="0.01" iyz="0" izz="0.01"/>
      <origin rpy="0 0 0" xyz="0 0 0"/>
    </inertial>
    <!--
      <inertial>
        <origin xyz="0 0 0" rpy="0 0 0" />
        <mass value="0.29364"/>
        <inertia ixx="0.01" ixy="0" ixz="0" iyy="0.01" iyz="0" izz="0.01" />
      </inertial>
-->
    <visual>
      <origin rpy="0 0 0" xyz="0 0 0"/>
      <geometry>
        <mesh filename="package://mp400_description/meshes/lwa4p/arm_1_link.dae"/>
      </geometry>
      <material name="Schunk/DarkGrey"/>
    </visual>
    <collision>
      <origin rpy="0 0 0" xyz="0 0 0"/>
      <geometry>
        <mesh filename="package://mp400_description/meshes/lwa4p/arm_1_link.stl"/>
      </geometry>
    </collision>
  </link>
  <!-- joint between arm_1_link and arm_2_link -->
  <joint name="arm_2_joint" type="revolute">
    <origin rpy="1.5708 0 0" xyz="0 0 0"/>
    <parent link="arm_1_link"/>
    <child link="arm_2_link"/>
    <axis xyz="0 0 1"/>
    <limit effort="250" lower="-2.95" upper="2.95" velocity="1.25"/>
    <!-- This is useful when the arm is mounted standing on a table -->
    <!-- <safety_controller k_position="20" k_velocity="25" soft_lower_limit="${-1.9 + safety_offset}" soft_upper_limit="${1.9 - safety_offset}" /> -->
  </joint>
  <!-- eff = "370" -->
  <link name="arm_2_link">
    <inertial>
      <mass value="0.29364"/>
      <inertia ixx="0.01" ixy="0" ixz="0" iyy="0.01" iyz="0" izz="0.01"/>
      <origin rpy="0 0 0" xyz="0 0 0"/>
    </inertial>
    <!--<inertial>
        <origin xyz="0 0 0" rpy="0 0 0"/>
        <mass value="1.68311"/>
        <inertia ixx="0.03" ixy="0" ixz="0" iyy="0.03" iyz="0" izz="0.03" />
      </inertial>-->
    <visual>
      <origin rpy="0 0 0" xyz="0 0 0"/>
      <geometry>
        <mesh filename="package://mp400_description/meshes/lwa4p/arm_2_link.dae"/>
      </geometry>
      <material name="Schunk/Blue"/>
    </visual>
    <collision>
      <origin rpy="0 0 0" xyz="0 0 0"/>
      <geometry>
        <mesh filename="package://mp400_description/meshes/lwa4p/arm_2_link.stl"/>
      </geometry>
    </collision>
  </link>
  <!-- joint between arm_2_link and arm_3_link -->
  <joint name="arm_3_joint" type="revolute">
    <origin rpy="0 3.14159 0" xyz="0 0.350 0"/>
    <parent link="arm_2_link"/>
    <child link="arm_3_link"/>
    <axis xyz="0 0 1"/>
    <limit effort="200" lower="-2.95" upper="2.95" velocity="1.25"/>
    <!--<safety_controller k_position="20" k_velocity="25" soft_lower_limit="${-2.7+ safety_offset}" soft_upper_limit="${2.7 - safety_offset}" />-->
  </joint>
  <!-- eff = "176" -->
  <link name="arm_3_link">
    <!-- <xacro:default_inertial mass="0.29364"/> 2.1-->
    <inertial>
      <origin rpy="0 0 1.5708" xyz="0 0 0"/>
      <mass value="0.29364"/>
      <inertia ixx="0.03" ixy="0" ixz="0" iyy="0.03" iyz="0" izz="0.03"/>
    </inertial>
    <visual>
      <origin rpy="0 0 0" xyz="0 0 0"/>
      <geometry>
        <mesh filename="package://mp400_description/meshes/lwa4p/arm_3_link.dae"/>
      </geometry>
      <material name="Schunk/DarkGrey"/>
    </visual>
    <collision>
      <origin rpy="0 0 0" xyz="0 0 0"/>
      <geometry>
        <mesh filename="package://mp400_description/meshes/lwa4p/arm_3_link.stl"/>
      </geometry>
    </collision>
  </link>
  <!-- joint between arm_3_link and arm_4_link -->
  <joint name="arm_4_joint" type="revolute">
    <origin rpy="-1.5708 3.14159 0" xyz="0 0 0"/>
    <parent link="arm_3_link"/>
    <child link="arm_4_link"/>
    <axis xyz="0 0 1"/>
    <limit effort="150" lower="-2.95" upper="2.95" velocity="1.25"/>
  </joint>
  <!-- eff = "176" -->
  <link name="arm_4_link">
    <inertial>
      <mass value="0.19364"/>
      <inertia ixx="0.01" ixy="0" ixz="0" iyy="0.01" iyz="0" izz="0.01"/>
      <origin rpy="0 0 0" xyz="0 0 0"/>
    </inertial>
    <!-- 0.29364 -->
    <!--<inertial>
        <origin xyz="0 0 0" rpy="0 0 0"/>
        <mass value="1.68311"/>
        <inertia ixx="0.03" ixy="0" ixz="0" iyy="0.03" iyz="0" izz="0.03" />
      </inertial>-->
    <visual>
      <origin rpy="0 0 0" xyz="0 0 0"/>
      <geometry>
        <mesh filename="package://mp400_description/meshes/lwa4p/arm_4_link.dae"/>
      </geometry>
      <material name="Schunk/Blue"/>
    </visual>
    <collision>
      <origin rpy="0 0 0" xyz="0 0 0"/>
      <geometry>
        <mesh filename="package://mp400_description/meshes/lwa4p/arm_4_link.stl"/>
      </geometry>
    </collision>
  </link>
  <!-- joint between arm_4_link and arm_5_link -->
  <joint name="arm_5_joint" type="revolute">
    <origin rpy="1.5708 0 3.14159" xyz="0 0.005263 0.305"/>
    <parent link="arm_4_link"/>
    <child link="arm_5_link"/>
    <axis xyz="0 0 1"/>
    <limit effort="100" lower="-2.95" upper="2.95" velocity="1.25"/>
  </joint>
  <!-- eff = "41.6" -->
  <link name="arm_5_link">
    <inertial>
      <mass value="0.15364"/>
      <inertia ixx="0.01" ixy="0" ixz="0" iyy="0.01" iyz="0" izz="0.01"/>
      <origin rpy="0 0 0" xyz="0 0 0"/>
    </inertial>
    <!-- 0.29364 -->
    <!--<inertial>
        <origin xyz="0 0 0" rpy="0 0 0"/>
        <mass value="0.807"/>
        <inertia ixx="0.03" ixy="0" ixz="0" iyy="0.03" iyz="0" izz="0.03" />
      </inertial>-->
    <visual>
      <origin rpy="0 0 0" xyz="0 0 0"/>
      <geometry>
        <mesh filename="package://mp400_description/meshes/lwa4p/arm_5_link.dae"/>
      </geometry>
      <material name="Schunk/DarkGrey"/>
    </visual>
    <collision>
      <origin rpy="0 0 0" xyz="0 0 0"/>
      <geometry>
        <mesh filename="package://mp400_description/meshes/lwa4p/arm_5_link.stl"/>
      </geometry>
    </collision>
  </link>
  <!-- joint between arm_5_link and arm_6_link -->
  <joint name="arm_6_joint" type="revolute">
    <origin rpy="-1.5708 0 0" xyz="0 0 0"/>
    <parent link="arm_5_link"/>
    <child link="arm_6_link"/>
    <axis xyz="0 0 1"/>
    <limit effort="50" lower="-2.947" upper="2.947" velocity="1.25"/>
    <!--safety_controller k_position="20" k_velocity="25" soft_lower_limit="${-2.09 + 0.01}" soft_upper_limit="${2.09 - 0.01}" /-->
  </joint>
  <link name="arm_6_link">
    <inertial>
      <mass value="0.10364"/>
      <inertia ixx="0.01" ixy="0" ixz="0" iyy="0.01" iyz="0" izz="0.01"/>
      <origin rpy="0 0 0" xyz="0 0 0"/>
    </inertial>
    <!-- 0.29364 -->
    <!--<inertial>
        <origin xyz="0 0 0" rpy="0 0 0"/>
        <mass value="0.819"/>
        <inertia ixx="0.01" ixy="0" ixz="0" iyy="0.01" iyz="0" izz="0.01" />
      </inertial>-->
    <visual>
      <origin rpy="0 0 0" xyz="0 0 0"/>
      <geometry>
        <mesh filename="package://mp400_description/meshes/lwa4p/arm_6_link.dae"/>
      </geometry>
      <material name="Schunk/DarkGrey"/>
    </visual>
    <collision>
      <origin rpy="0 0 0" xyz="0 0 0"/>
      <geometry>
        <mesh filename="package://mp400_description/meshes/lwa4p/arm_6_link.stl"/>
      </geometry>
    </collision>
  </link>
  <!-- joint between arm_6_link and tcp_link -->
  <!--<joint name="${name}_tcp_joint" type="fixed">
      <origin xyz="0 0 0.08" rpy="0 0 0" />
      <parent link="${name}_6_link"/>
      <child link="${name}_tcp_link"/>
    </joint>
    <link name="${name}_tcp_link">
    </link>-->
  <gazebo reference="arm_0_link">
    <gravity>true</gravity>
    <self_collide>false</self_collide>
    <material value="Schunk/DarkGrey"/>
  </gazebo>
  <gazebo reference="arm_1_link">
    <gravity>true</gravity>
    <self_collide>false</self_collide>
    <material value="Schunk/DarkGrey"/>
  </gazebo>
  <gazebo reference="arm_2_link">
    <gravity>true</gravity>
    <self_collide>false</self_collide>
    <material value="Schunk/Blue"/>
  </gazebo>
  <gazebo reference="arm_3_link">
    <gravity>true</gravity>
    <self_collide>false</self_collide>
    <material value="Schunk/DarkGrey"/>
  </gazebo>
  <gazebo reference="arm_4_link">
    <gravity>true</gravity>
    <self_collide>false</self_collide>
    <material value="Schunk/Blue"/>
  </gazebo>
  <gazebo reference="arm_5_link">
    <gravity>true</gravity>
    <self_collide>false</self_collide>
    <material value="Schunk/DarkGrey"/>
  </gazebo>
  <gazebo reference="arm_6_link">
    <gravity>true</gravity>
    <self_collide>false</self_collide>
    <material value="Schunk/DarkGrey"/>
  </gazebo>
  <transmission name="arm_1_trans">
    <type>transmission_interface/SimpleTransmission</type>
    <joint name="arm_1_joint">
      <hardwareInterface>hardware_interface/EffortJointInterface</hardwareInterface>
      <!--<hardwareInterface>PositionJointInterface</hardwareInterface>
        <hardwareInterface>VelocityJointInterface</hardwareInterface>-->
    </joint>
    <actuator name="arm_1_motor">
      <hardwareInterface>hardware_interface/EffortJointInterface</hardwareInterface>
      <mechanicalReduction>1</mechanicalReduction>
    </actuator>
  </transmission>
  <transmission name="arm_2_trans">
    <type>transmission_interface/SimpleTransmission</type>
    <joint name="arm_2_joint">
      <hardwareInterface>hardware_interface/EffortJointInterface</hardwareInterface>
      <!--<hardwareInterface>PositionJointInterface</hardwareInterface>
        <hardwareInterface>VelocityJointInterface</hardwareInterface>-->
    </joint>
    <actuator name="arm_2_motor">
      <hardwareInterface>hardware_interface/EffortJointInterface</hardwareInterface>
      <mechanicalReduction>1</mechanicalReduction>
    </actuator>
  </transmission>
  <transmission name="arm_3_trans">
    <type>transmission_interface/SimpleTransmission</type>
    <joint name="arm_3_joint">
      <hardwareInterface>hardware_interface/EffortJointInterface</hardwareInterface>
      <!--<hardwareInterface>PositionJointInterface</hardwareInterface>
        <hardwareInterface>VelocityJointInterface</hardwareInterface>-->
    </joint>
    <actuator name="arm_3_motor">
      <hardwareInterface>hardware_interface/EffortJointInterface</hardwareInterface>
      <mechanicalReduction>1</mechanicalReduction>
    </actuator>
  </transmission>
  <transmission name="arm_4_trans">
    <type>transmission_interface/SimpleTransmission</type>
    <joint name="arm_4_joint">
      <hardwareInterface>hardware_interface/EffortJointInterface</hardwareInterface>
      <!--<hardwareInterface>PositionJointInterface</hardwareInterface>
        <hardwareInterface>VelocityJointInterface</hardwareInterface>-->
    </joint>
    <actuator name="arm_4_motor">
      <hardwareInterface>hardware_interface/EffortJointInterface</hardwareInterface>
      <mechanicalReduction>1</mechanicalReduction>
    </actuator>
  </transmission>
  <transmission name="arm_5_trans">
    <type>transmission_interface/SimpleTransmission</type>
    <joint name="arm_5_joint">
      <hardwareInterface>hardware_interface/EffortJointInterface</hardwareInterface>
      <!--<hardwareInterface>PositionJointInterface</hardwareInterface>
        <hardwareInterface>VelocityJointInterface</hardwareInterface>-->
    </joint>
    <actuator name="arm_5_motor">
      <hardwareInterface>hardware_interface/EffortJointInterface</hardwareInterface>
      <mechanicalReduction>1</mechanicalReduction>
    </actuator>
  </transmission>
  <transmission name="arm_6_trans">
    <type>transmission_interface/SimpleTransmission</type>
    <joint name="arm_6_joint">
      <hardwareInterface>hardware_interface/EffortJointInterface</hardwareInterface>
      <!--<hardwareInterface>PositionJointInterface</hardwareInterface>
        <hardwareInterface>VelocityJointInterface</hardwareInterface>-->
    </joint>
    <actuator name="arm_6_motor">
      <hardwareInterface>hardware_interface/EffortJointInterface</hardwareInterface>
      <mechanicalReduction>1</mechanicalReduction>
    </actuator>
  </transmission>
  <material name="aluminum">
    <color rgba="0.5 0.5 0.5 1"/>
  </material>

  <joint name="pg70_palm_joint" type="fixed">
      <parent link="arm_6_link" />
      <child link="pg70_palm_link" />
      <origin rpy="0 0 0" xyz="0 0 0.075" />
  </joint>
  <link name="pg70_palm_link">
      <visual>
          <geometry>
              <mesh filename="package://schunk_description/meshes/pg70/pg70.dae" />
          </geometry>
          <material name="blue">
              <color rgba="0 0 1 1" />
          </material>
      </visual>
      <collision>
          <geometry>
              <mesh filename="package://schunk_description/meshes/pg70/pg70.dae" />
          </geometry>
          <material name="blue">
              <color rgba="0 0 1 1" />
          </material>
      </collision>

<inertial>
          <mass value="0.1" />
          <inertia ixx="0.03" iyy="0.03" izz="0.03" ixy="0.0" ixz="0.0" iyz="0.0" />
      </inertial>

  </link>
  <joint name="pg70_finger_left_joint" type="prismatic">
      <parent link="pg70_palm_link" />
      <child link="pg70_finger_left_link" />
      <limit effort="100" lower="-0.001" upper="0.04" velocity="2.0" />
      <origin xyz="0 0 0.0789" rpy="0 0 0" />
      <axis xyz="0 1 0" />
  </joint>
  <link name="pg70_finger_left_link">
      <visual>
          <geometry>
              <box size="0.03 0.01 0.01" />
          </geometry>
          <material name="black">
              <color rgba="0 0 0 1" />
          </material>
      </visual>
      <collision>
          <geometry>
              <box size="0.03 0.01 0.01" />
          </geometry>
          <material name="black" />
      </collision>

<inertial>
          <mass value="0.1" />
          <inertia ixx="0.03" iyy="0.03" izz="0.03" ixy="0.0" ixz="0.0" iyz="0.0" />
      </inertial>

  </link>
  <joint name="pg70_fingertip_left_joint" type="fixed">
      <parent link="pg70_finger_left_link" />
      <child link="pg70_fingertip_left_link" />
      <origin xyz="0 0.01 0.045" rpy="0 0 0" />
  </joint>
  <link name="pg70_fingertip_left_link">
      <visual>
          <geometry>
              <box size="0.03 0.01 0.1" />
          </geometry>
          <material name="silver">
              <color rgba="0.8 0.8 0.8 1" />
          </material>
      </visual>
      <collision>
          <geometry>
              <box size="0.03 0.01 0.1" />
          </geometry>
          <material name="black" />
      </collision>

<inertial>
          <mass value="0.1" />
          <inertia ixx="0.03" iyy="0.03" izz="0.03" ixy="0.0" ixz="0.0" iyz="0.0" />
      </inertial>

  </link>


  <!-- extensions -->
  <gazebo reference="pg70_palm_link">
      <gravity>true</gravity>
      <self_collide>false</self_collide>
      <material>Schunk/LightGrey</material>
  </gazebo>
  <gazebo reference="pg70_finger_left_link">
      <gravity>true</gravity>
      <self_collide>false</self_collide>
      <material>Schunk/LightGrey</material>
  </gazebo>
  <gazebo reference="pg70_finger_right_link">
      <gravity>true</gravity>
      <self_collide>false</self_collide>
      <material>Schunk/LightGrey</material>
  </gazebo>
  <!-- finger1 -->
  <transmission name="pg70_finger_left_trans">
      <type>transmission_interface/SimpleTransmission</type>
      <joint name="pg70_finger_left_joint">
          <hardwareInterface>EffortJointInterface</hardwareInterface>
          <hardwareInterface>PositionJointInterface</hardwareInterface>
          <hardwareInterface>VelocityJointInterface</hardwareInterface>
      </joint>
      <actuator name="pg70_finger_left_motor">
          <mechanicalReduction>0.5</mechanicalReduction>
      </actuator>
  </transmission>
  <!-- finger2 - mimic -->

  <!-- gazebo_plugin for arm -->
  <gazebo>
      <plugin filename="libhwi_switch_gazebo_ros_control.so" name="ros_control">
          <robotNamespace>arm</robotNamespace>
          <filterJointsParam>joint_names</filterJointsParam>
      </plugin>

      <plugin filename="libhwi_switch_gazebo_ros_control.so" name="ros_control">
          <robotNamespace>gripper</robotNamespace>
          <filterJointsParam>joint_names</filterJointsParam>
    </plugin>
  </gazebo>

  <!-- camera body, with origin at bottom screw mount -->
  <joint name="camera_joint" type="fixed">
    <origin rpy="0 0 0" xyz="0.2 0 0"/>
    <parent link="schunk_base_link"/>
    <child link="camera_link"/>
  </joint>
  <link name="camera_link">
    <visual>
      <origin rpy="0.77079632679 0 1.57079632679" xyz="0.0149 0.0 0.0125"/>
      <!--<origin xyz="-0.25 0.0 1.425" rpy="${M_PI/2} 0 ${-M_PI/2}"/>-->
      <geometry>
        <!-- <box size="${d435_cam_width} ${d435_cam_height} ${d435_cam_depth}"/> -->
        <mesh filename="package://mp400_description/meshes/d435_camera/d435.dae"/>
        <!--<mesh filename="package://realsense2_camera/meshes/d435/d435.dae" />-->
      </geometry>
      <material name="aluminum"/>
    </visual>
    <collision>
      <origin rpy="0 0 0" xyz="0.0 0.0 0.0125"/>
      <!--<origin xyz="0.0 0.0 1.425" rpy="0 0 0"/>-->
      <geometry>
        <box size="0.02505 0.09 0.025"/>
      </geometry>
    </collision>
    <inertial>
      <!-- The following are not reliable values, and should not be used for modeling -->
      <mass value="0.564"/>
      <origin xyz="0 0 0"/>
      <inertia ixx="0.003881243" ixy="0.0" ixz="0.0" iyy="0.000498940" iyz="0.0" izz="0.003879257"/>
    </inertial>
  </link>
  <!-- camera depth joints and links -->
  <joint name="camera_depth_joint" type="fixed">
    <origin rpy="0 0 0" xyz="0.0149 0.0175 0.0125"/>
    <parent link="camera_link"/>
    <child link="camera_depth_frame"/>
  </joint>
  <link name="camera_depth_frame"/>
  <joint name="camera_depth_optical_joint" type="fixed">
    <origin rpy="-1.57079632679 0 -1.57079632679" xyz="0 0 0"/>
    --&gt;

    <!--<origin xyz="0 0 0" rpy="0 0 0" />-->
    <parent link="camera_depth_frame"/>
    <child link="camera_depth_optical_frame"/>
  </joint>
  <link name="camera_depth_optical_frame"/>
  <!-- camera left IR joints and links -->
  <joint name="camera_left_ir_joint" type="fixed">
    <origin rpy="0 0 0" xyz="0 0.0 0"/>
    <parent link="camera_depth_frame"/>
    <child link="camera_left_ir_frame"/>
  </joint>
  <link name="camera_left_ir_frame"/>
  <joint name="camera_left_ir_optical_joint" type="fixed">
    <origin rpy="-1.57079632679 0 -1.57079632679" xyz="0 0 0"/>
    <parent link="camera_left_ir_frame"/>
    <child link="camera_left_ir_optical_frame"/>
  </joint>
  <link name="camera_left_ir_optical_frame"/>
  <!-- camera right IR joints and links -->
  <joint name="camera_right_ir_joint" type="fixed">
    <origin rpy="0 0 0" xyz="0 -0.05 0"/>
    <parent link="camera_depth_frame"/>
    <child link="camera_right_ir_frame"/>
  </joint>
  <link name="camera_right_ir_frame"/>
  <joint name="camera_right_ir_optical_joint" type="fixed">
    <origin rpy="-1.57079632679 0 -1.57079632679" xyz="0 0 0"/>
    <parent link="camera_right_ir_frame"/>
    <child link="camera_right_ir_optical_frame"/>
  </joint>
  <link name="camera_right_ir_optical_frame"/>
  <!-- camera color joints and links -->
  <joint name="camera_color_joint" type="fixed">
    <origin rpy="0 0 0" xyz="0 0.015 0"/>
    <parent link="camera_depth_frame"/>
    <child link="camera_color_frame"/>
  </joint>
  <link name="camera_color_frame"/>
  <joint name="camera_color_optical_joint" type="fixed">
    <origin rpy="-1.57079632679 0 -1.57079632679" xyz="0 0 0"/>
    <parent link="camera_color_frame"/>
    <child link="camera_color_optical_frame"/>
  </joint>
  <link name="camera_color_optical_frame"/>



</robot>
